Workbook

Sheet Transactions
A1: Date | B1: Type | C1: Category | D1: Description | E1: Amount | F1: Payment Method | G1: Notes
A2: 46127 | B2: Income | C2: Salary | D2: Salary | E2: 6512.67 | F2: GIRO
A3: 46127 | B3: Expense | C3: Subscription | D3: Prime | E3: 4.999 | F3: Credit Card | G3: Citi Cash+
A4: 46130 | B4: Expense | C4: Shopping | D4: Shoppee | E4: 6.58 | F4: Credit Card | G4: Citi Cash+
A5: 46131 | B5: Expense | C5: Shopping | D5: Shoppee | E5: 5.46 | F5: Credit Card | G5: Citi Cash+
A6: 46127 | B6: Expense | C6: Shopping | D6: Tiktok | E6: 6.54 | F6: Credit Card | G6: Citi Rewards
A7: 46128 | B7: Expense | C7: Food | D7: Chicken Rice | E7: 6 | F7: Credit Card | G7: Citi Rewards
A8: 46127 | B8: Expense | C8: Transport | D8: Bus | E8: 0.1 | F8: Credit Card | G8: Citi Rewards
A9: 46129 | B9: Expense | C9: Food | D9: Chicken Rice | E9: 8.1 | F9: Credit Card | G9: Citi Rewards
A10: 46130 | B10: Expense | C10: Shopping | D10: Amazon Cookie | E10: 16.5 | F10: Credit Card | G10: Citi Rewards
A11: 46130 | B11: Expense | C11: Subscription | D11: iCloud | E11: 13.98 | F11: Credit Card | G11: Citi Rewards
A12: 46130 | B12: Expense | C12: Grocery | D12: Fairprice | E12: 25.88 | F12: Credit Card | G12: Citi Rewards
A13: 46131 | B13: Expense | C13: Entertainment | D13: Pokemon Card | E13: 18 | F13: Credit Card | G13: Citi Rewards
A14: 46129 | B14: Expense | C14: Subscription | D14: Spotify | E14: 17.46 | F14: Debit Card | G14: DBS
... A16: 46131 | B16: Expense | C16: Food | D16: Popeye | E16: 13.7 | F16: Credit Card | G16: Yuu
A17: 46127 | B17: Income | C17: Gift | D17: Tamil New Year | E17: 200 | F17: Cash
A18: 46127 | B18: Income | C18: Misc | D18: Dental Refund | E18: 20 | F18: Cash
A19: 46131 | B19: Expense | C19: Food | D19: Subway | E19: 13 | F19: Credit Card | G19: Citi Rewards
A20: 46132 | B20: Expense | C20: Food | D20: Chicken Rice | E20: 7.1 | F20: Credit Card | G20: Citi Rewards
A21: 46132 | B21: Expense | C21: Transport | D21: Bus | E21: 0.2 | F21: Credit Card | G21: Citi Rewards
A22: 46132 | B22: Expense | C22: Grocery | D22: Fairprice | E22: 14.44 | F22: Credit Card | G22: Citi Rewards
A23: 46132 | B23: Expense | C23: Grocery | D23: Fairprice | E23: 18.27 | F23: Credit Card | G23: Citi Rewards
A24: 46134 | B24: Expense | C24: Food | D24: Chicken Rice | E24: 5.4 | F24: Credit Card | G24: Citi Rewards
A25: 46134 | B25: Expense | C25: Food | D25: Siew Mai | E25: 5.1 | F25: Credit Card | G25: Citi Rewards
A26: 46134 | B26: Expense | C26: Grocery | D26: Fairprice | E26: 3.1 | F26: Credit Card | G26: Citi Rewards
A27: 46135 | B27: Expense | C27: Transport | D27: Bus | E27: 0.2 | F27: Credit Card | G27: Citi Rewards
A28: 46136 | B28: Expense | C28: Food | D28: Stuffd | E28: 15.1 | F28: Credit Card | G28: Citi Rewards
A29: 46137 | B29: Expense | C29: Misc | D29: Donation | E29: 125 | F29: Credit Card | G29: Citi Rewards
A30: 46138 | B30: Expense | C30: Subscription | D30: Youtube | E30: 17.98 | F30: Credit Card | G30: Citi Rewards
... A37: 46135 | B37: Expense | C37: Food | D37: Lunch with Team | E37: 18 | F37: Debit Card | G37: DBS
A38: 46136 | B38: Income | C38: Salary | D38: Nsfit | E38: 25.52 | G38: DBS
A39: 46139 | B39: Income | C39: Other Income | D39: CRWV stock profit | E39: 1482 | G39: DBS
A40: 46143 | B40: Expense | C40: Transport | D40: Parking | E40: 1.2 | G40: DBS
A41: 46138 | B41: Expense | C41: Grocery | D41: Fairprice | E41: 5.86 | F41: Credit Card | G41: Citi Rewards
A42: 46139 | B42: Expense | C42: Food | D42: Wokhey | E42: 7.9 | F42: Credit Card | G42: Citi Rewards
A43: 46139 | B43: Expense | C43: Food | E43: 0.17 | F43: Credit Card | G43: Citi Rewards
A44: 46140 | B44: Expense | C44: Food | D44: Citi Cafe | E44: 7.8 | F44: Credit Card | G44: Citi Rewards
A45: 46140 | B45: Expense | C45: Transport | D45: Bus | E45: 0.1 | F45: Credit Card | G45: Citi Rewards
A46: 46141 | B46: Expense | C46: Food | D46: Stuffd | E46: 11.5 | F46: Credit Card | G46: Citi Rewards
A47: 46142 | B47: Expense | C47: Food | D47: Andes | E47: 14.5 | F47: Credit Card | G47: Citi Rewards
...

Sheet Dashboard
B2: Personal Finance Dashboard
B3: Auto-syncs from the Transactions tab — all figures in SGD
B5: Total Income (This Month) | D5: Total Expense (This Month) | F5: Net Cashflow (This Month)
B6: =SUMIFS(Transactions!E:E,Transactions!B:B,"Income",Transactions!A:A,">="&DATE(YEAR(TODAY()),MONTH(TODAY()),1),Transactions!A:A,"<="&EOMONTH(TODAY(),0)) -> 6776.5 | D6: =SUMIFS(Transactions!E:E,Transactions!B:B,"Expense",Transactions!A:A,">="&DATE(YEAR(TODAY()),MONTH(TODAY()),1),Transactions!A:A,"<="&EOMONTH(TODAY(),0)) -> 3776.96 | F6: =B6-D6 -> 2999.54
B8: Biggest Expense Category | D8: Avg Daily Spending (This Month) | F8: Transactions Logged (This Month)
B9: {=IFERROR(INDEX($J$22:$J$32,MATCH(MAX($K$22:$K$32),$K$22:$K$32,0)),"—")} -> Family | D9: =IFERROR(D6/DAY(EOMONTH(TODAY(),0)),0) -> 121.83742 | F9: =COUNTIFS(Transactions!A:A,">="&DATE(YEAR(TODAY()),MONTH(TODAY()),1),Transactions!A:A,"<="&EOMONTH(TODAY(),0)) -> 104
J11: Monthly Trend (Income vs Expense)
J12: Month | K12: Income | L12: Expense
J13: Feb 2026 | K13: =SUMIFS(Transactions!E:E,Transactions!B:B,"Income",Transactions!A:A,">="&DATE(2026,2,1),Transactions!A:A,"<"&DATE(2026,3,1)) -> 0 | L13: =SUMIFS(Transactions!E:E,Transactions!B:B,"Expense",Transactions!A:A,">="&DATE(2026,2,1),Transactions!A:A,"<"&DATE(2026,3,1)) -> 0
J14: Mar 2026 | K14: =SUMIFS(Transactions!E:E,Transactions!B:B,"Income",Transactions!A:A,">="&DATE(2026,3,1),Transactions!A:A,"<"&DATE(2026,4,1)) -> 0 | L14: =SUMIFS(Transactions!E:E,Transactions!B:B,"Expense",Transactions!A:A,">="&DATE(2026,3,1),Transactions!A:A,"<"&DATE(2026,4,1)) -> 0
J15: Apr 2026 | K15: =SUMIFS(Transactions!E:E,Transactions!B:B,"Income",Transactions!A:A,">="&DATE(2026,4,1),Transactions!A:A,"<"&DATE(2026,5,1)) -> 8681.09 | L15: =SUMIFS(Transactions!E:E,Transactions!B:B,"Expense",Transactions!A:A,">="&DATE(2026,4,1),Transactions!A:A,"<"&DATE(2026,5,1)) -> 590.359
J16: May 2026 | K16: =SUMIFS(Transactions!E:E,Transactions!B:B,"Income",Transactions!A:A,">="&DATE(2026,5,1),Transactions!A:A,"<"&DATE(2026,6,1)) -> 6776.5 | L16: =SUMIFS(Transactions!E:E,Transactions!B:B,"Expense",Transactions!A:A,">="&DATE(2026,5,1),Transactions!A:A,"<"&DATE(2026,6,1)) -> 3776.96
J17: Jun 2026 | K17: =SUMIFS(Transactions!E:E,Transactions!B:B,"Income",Transactions!A:A,">="&DATE(2026,6,1),Transactions!A:A,"<"&DATE(2026,7,1)) -> 0 | L17: =SUMIFS(Transactions!E:E,Transactions!B:B,"Expense",Transactions!A:A,">="&DATE(2026,6,1),Transactions!A:A,"<"&DATE(2026,7,1)) -> 0
J18: Jul 2026 | K18: =SUMIFS(Transactions!E:E,Transactions!B:B,"Income",Transactions!A:A,">="&DATE(2026,7,1),Transactions!A:A,"<"&DATE(2026,8,1)) -> 0 | L18: =SUMIFS(Transactions!E:E,Transactions!B:B,"Expense",Transactions!A:A,">="&DATE(2026,7,1),Transactions!A:A,"<"&DATE(2026,8,1)) -> 0
J20: Expense by Category (All-Time)
J21: Category | K21: Amount
J22: Food | K22: =SUMIFS(Transactions!E:E,Transactions!B:B,"Expense",Transactions!C:C,"Food") -> 847.14
J23: Transport | K23: =SUMIFS(Transactions!E:E,Transactions!B:B,"Expense",Transactions!C:C,"Transport") -> 110.18
J24: Bills | K24: =SUMIFS(Transactions!E:E,Transactions!B:B,"Expense",Transactions!C:C,"Bills") -> 240
J25: Shopping | K25: =SUMIFS(Transactions!E:E,Transactions!B:B,"Expense",Transactions!C:C,"Shopping") -> 486.98
J26: Subscription | K26: =SUMIFS(Transactions!E:E,Transactions!B:B,"Expense",Transactions!C:C,"Subscription") -> 437.369
J27: Entertainment | K27: =SUMIFS(Transactions!E:E,Transactions!B:B,"Expense",Transactions!C:C,"Entertainment") -> 180
J28: Health | K28: =SUMIFS(Transactions!E:E,Transactions!B:B,"Expense",Transactions!C:C,"Health") -> 0
J29: Family | K29: =SUMIFS(Transactions!E:E,Transactions!B:B,"Expense",Transactions!C:C,"Family") -> 1000
J30: Travel | K30: =SUMIFS(Transactions!E:E,Transactions!B:B,"Expense",Transactions!C:C,"Travel") -> 563.95
J31: Education | K31: =SUMIFS(Transactions!E:E,Transactions!B:B,"Expense",Transactions!C:C,"Education") -> 8.88
J32: Misc | K32: =SUMIFS(Transactions!E:E,Transactions!B:B,"Expense",Transactions!C:C,"Misc") -> 199
J34: Weekly Spending Trend
J35: Week Start | K35: Spending
J36: 46048 | K36: =SUMIFS(Transactions!E:E,Transactions!B:B,"Expense",Transactions!A:A,">="&DATE(2026,1,26),Transactions!A:A,"<"&DATE(2026,2,2)) -> 0
J37: 46055 | K37: =SUMIFS(Transactions!E:E,Transactions!B:B,"Expense",Transactions!A:A,">="&DATE(2026,2,2),Transactions!A:A,"<"&DATE(2026,2,9)) -> 0
J38: 46062 | K38: =SUMIFS(Transactions!E:E,Transactions!B:B,"Expense",Transactions!A:A,">="&DATE(2026,2,9),Transactions!A:A,"<"&DATE(2026,2,16)) -> 0
J39: 46069 | K39: =SUMIFS(Transactions!E:E,Transactions!B:B,"Expense",Transactions!A:A,">="&DATE(2026,2,16),Transactions!A:A,"<"&DATE(2026,2,23)) -> 0
J40: 46076 | K40: =SUMIFS(Transactions!E:E,Transactions!B:B,"Expense",Transactions!A:A,">="&DATE(2026,2,23),Transactions!A:A,"<"&DATE(2026,3,2)) -> 0
J41: 46083 | K41: =SUMIFS(Transactions!E:E,Transactions!B:B,"Expense",Transactions!A:A,">="&DATE(2026,3,2),Transactions!A:A,"<"&DATE(2026,3,9)) -> 0
J42: 46090 | K42: =SUMIFS(Transactions!E:E,Transactions!B:B,"Expense",Transactions!A:A,">="&DATE(2026,3,9),Transactions!A:A,"<"&DATE(2026,3,16)) -> 0
J43: 46097 | K43: =SUMIFS(Transactions!E:E,Transactions!B:B,"Expense",Transactions!A:A,">="&DATE(2026,3,16),Transactions!A:A,"<"&DATE(2026,3,23)) -> 0
J44: 46104 | K44: =SUMIFS(Transactions!E:E,Transactions!B:B,"Expense",Transactions!A:A,">="&DATE(2026,3,23),Transactions!A:A,"<"&DATE(2026,3,30)) -> 0
J45: 46111 | K45: =SUMIFS(Transactions!E:E,Transactions!B:B,"Expense",Transactions!A:A,">="&DATE(2026,3,30),Transactions!A:A,"<"&DATE(2026,4,6)) -> 0
J46: 46118 | K46: =SUMIFS(Transactions!E:E,Transactions!B:B,"Expense",Transactions!A:A,">="&DATE(2026,4,6),Transactions!A:A,"<"&DATE(2026,4,13)) -> 0
...

Sheet Report
B2: Financial Report | Z2: =IFERROR(IF(Transactions!B2="Expense",Transactions!E2+ROW()/10000000,""),"") | AA2: =IFERROR(IF(Transactions!B2="Expense",Transactions!A2,""),"") | AB2: =IFERROR(IF(Transactions!B2="Expense",Transactions!C2,""),"") | AC2: =IFERROR(IF(Transactions!B2="Expense",Transactions!D2,""),"") | AD2: =IFERROR(IF(Transactions!B2="Expense",Transactions!E2,""),"")
B3: Auto-generated summaries from Transactions | Z3: =IFERROR(IF(Transactions!B3="Expense",Transactions!E3+ROW()/10000000,""),"") -> 4.9990003 | AA3: =IFERROR(IF(Transactions!B3="Expense",Transactions!A3,""),"") -> 46127 | AB3: =IFERROR(IF(Transactions!B3="Expense",Transactions!C3,""),"") -> Subscription | AC3: =IFERROR(IF(Transactions!B3="Expense",Transactions!D3,""),"") -> Prime | AD3: =IFERROR(IF(Transactions!B3="Expense",Transactions!E3,""),"") -> 4.999
Z4: =IFERROR(IF(Transactions!B4="Expense",Transactions!E4+ROW()/10000000,""),"") -> 6.5800004 | AA4: =IFERROR(IF(Transactions!B4="Expense",Transactions!A4,""),"") -> 46130 | AB4: =IFERROR(IF(Transactions!B4="Expense",Transactions!C4,""),"") -> Shopping | AC4: =IFERROR(IF(Transactions!B4="Expense",Transactions!D4,""),"") -> Shoppee | AD4: =IFERROR(IF(Transactions!B4="Expense",Transactions!E4,""),"") -> 6.58
B5: 1. Monthly Summary | Z5: =IFERROR(IF(Transactions!B5="Expense",Transactions!E5+ROW()/10000000,""),"") -> 5.4600005 | AA5: =IFERROR(IF(Transactions!B5="Expense",Transactions!A5,""),"") -> 46131 | AB5: =IFERROR(IF(Transactions!B5="Expense",Transactions!C5,""),"") -> Shopping | AC5: =IFERROR(IF(Transactions!B5="Expense",Transactions!D5,""),"") -> Shoppee | AD5: =IFERROR(IF(Transactions!B5="Expense",Transactions!E5,""),"") -> 5.46
B6: Month | C6: Income | D6: Expense | E6: Net Savings | F6: Savings Rate | Z6: =IFERROR(IF(Transactions!B6="Expense",Transactions!E6+ROW()/10000000,""),"") -> 6.5400006 | AA6: =IFERROR(IF(Transactions!B6="Expense",Transactions!A6,""),"") -> 46127 | AB6: =IFERROR(IF(Transactions!B6="Expense",Transactions!C6,""),"") -> Shopping | AC6: =IFERROR(IF(Transactions!B6="Expense",Transactions!D6,""),"") -> Tiktok | AD6: =IFERROR(IF(Transactions!B6="Expense",Transactions!E6,""),"") -> 6.54
B7: Apr 2026 | C7: =SUMIFS(Transactions!E:E,Transactions!B:B,"Income",Transactions!A:A,">="&DATE(2026,4,1),Transactions!A:A,"<"&DATE(2026,5,1)) -> 8681.09 | D7: =SUMIFS(Transactions!E:E,Transactions!B:B,"Expense",Transactions!A:A,">="&DATE(2026,4,1),Transactions!A:A,"<"&DATE(2026,5,1)) -> 590.359 | E7: =C7-D7 -> 8090.731 | F7: =IFERROR((C7-D7)/C7,0) -> 0.93199483 | Z7: =IFERROR(IF(Transactions!B9="Expense",Transactions!E9+ROW()/10000000,""),"") -> 8.1000007 | AA7: =IFERROR(IF(Transactions!B9="Expense",Transactions!A9,""),"") -> 46129 | AB7: =IFERROR(IF(Transactions!B9="Expense",Transactions!C9,""),"") -> Food | AC7: =IFERROR(IF(Transactions!B9="Expense",Transactions!D9,""),"") -> Chicken Rice | AD7: =IFERROR(IF(Transactions!B9="Expense",Transactions!E9,""),"") -> 8.1
B8: May 2026 | C8: =SUMIFS(Transactions!E:E,Transactions!B:B,"Income",Transactions!A:A,">="&DATE(2026,5,1),Transactions!A:A,"<"&DATE(2026,6,1)) -> 6776.5 | D8: =SUMIFS(Transactions!E:E,Transactions!B:B,"Expense",Transactions!A:A,">="&DATE(2026,5,1),Transactions!A:A,"<"&DATE(2026,6,1)) -> 3776.96 | E8: =C8-D8 -> 2999.54 | F8: =IFERROR((C8-D8)/C8,0) -> 0.44263853 | Z8: =IFERROR(IF(Transactions!B10="Expense",Transactions!E10+ROW()/10000000,""),"") -> 16.500001 | AA8: =IFERROR(IF(Transactions!B10="Expense",Transactions!A10,""),"") -> 46130 | AB8: =IFERROR(IF(Transactions!B10="Expense",Transactions!C10,""),"") -> Shopping | AC8: =IFERROR(IF(Transactions!B10="Expense",Transactions!D10,""),"") -> Amazon Cookie | AD8: =IFERROR(IF(Transactions!B10="Expense",Transactions!E10,""),"") -> 16.5
B9: Jun 2026 | C9: =SUMIFS(Transactions!E:E,Transactions!B:B,"Income",Transactions!A:A,">="&DATE(2026,6,1),Transactions!A:A,"<"&DATE(2026,7,1)) -> 0 | D9: =SUMIFS(Transactions!E:E,Transactions!B:B,"Expense",Transactions!A:A,">="&DATE(2026,6,1),Transactions!A:A,"<"&DATE(2026,7,1)) -> 0 | E9: =C9-D9 -> 0 | F9: =IFERROR((C9-D9)/C9,0) -> 0 | Z9: =IFERROR(IF(Transactions!B11="Expense",Transactions!E11+ROW()/10000000,""),"") -> 13.980001 | AA9: =IFERROR(IF(Transactions!B11="Expense",Transactions!A11,""),"") -> 46130 | AB9: =IFERROR(IF(Transactions!B11="Expense",Transactions!C11,""),"") -> Subscription | AC9: =IFERROR(IF(Transactions!B11="Expense",Transactions!D11,""),"") -> iCloud | AD9: =IFERROR(IF(Transactions!B11="Expense",Transactions!E11,""),"") -> 13.98
B10: Jul 2026 | C10: =SUMIFS(Transactions!E:E,Transactions!B:B,"Income",Transactions!A:A,">="&DATE(2026,7,1),Transactions!A:A,"<"&DATE(2026,8,1)) -> 0 | D10: =SUMIFS(Transactions!E:E,Transactions!B:B,"Expense",Transactions!A:A,">="&DATE(2026,7,1),Transactions!A:A,"<"&DATE(2026,8,1)) -> 0 | E10: =C10-D10 -> 0 | F10: =IFERROR((C10-D10)/C10,0) -> 0 | Z10: =IFERROR(IF(Transactions!B12="Expense",Transactions!E12+ROW()/10000000,""),"") -> 25.880001 | AA10: =IFERROR(IF(Transactions!B12="Expense",Transactions!A12,""),"") -> 46130 | AB10: =IFERROR(IF(Transactions!B12="Expense",Transactions!C12,""),"") -> Grocery | AC10: =IFERROR(IF(Transactions!B12="Expense",Transactions!D12,""),"") -> Fairprice | AD10: =IFERROR(IF(Transactions!B12="Expense",Transactions!E12,""),"") -> 25.88
B11: Total | C11: =SUM(C7:C10) -> 15457.59 | D11: =SUM(D7:D10) -> 4367.319 | E11: =SUM(E7:E10) -> 11090.271 | F11: =IFERROR(E11/C11,0) -> 0.71746443 | Z11: =IFERROR(IF(Transactions!B13="Expense",Transactions!E13+ROW()/10000000,""),"") -> 18.000001 | AA11: =IFERROR(IF(Transactions!B13="Expense",Transactions!A13,""),"") -> 46131 | AB11: =IFERROR(IF(Transactions!B13="Expense",Transactions!C13,""),"") -> Entertainment | AC11: =IFERROR(IF(Transactions!B13="Expense",Transactions!D13,""),"") -> Pokemon Card | AD11: =IFERROR(IF(Transactions!B13="Expense",Transactions!E13,""),"") -> 18
Z12: =IFERROR(IF(Transactions!B14="Expense",Transactions!E14+ROW()/10000000,""),"") -> 17.460001 | AA12: =IFERROR(IF(Transactions!B14="Expense",Transactions!A14,""),"") -> 46129 | AB12: =IFERROR(IF(Transactions!B14="Expense",Transactions!C14,""),"") -> Subscription | AC12: =IFERROR(IF(Transactions!B14="Expense",Transactions!D14,""),"") -> Spotify | AD12: =IFERROR(IF(Transactions!B14="Expense",Transactions!E14,""),"") -> 17.46
Z13: =IFERROR(IF(Transactions!B15="Expense",Transactions!E15+ROW()/10000000,""),"") -> 11.800001 | AA13: =IFERROR(IF(Transactions!B15="Expense",Transactions!A15,""),"") -> 46127 | AB13: =IFERROR(IF(Transactions!B15="Expense",Transactions!C15,""),"") -> Food | AC13: =IFERROR(IF(Transactions!B15="Expense",Transactions!D15,""),"") -> Wokhey | AD13: =IFERROR(IF(Transactions!B15="Expense",Transactions!E15,""),"") -> 11.8
B14: 2. Category Spending Breakdown (All-Time) | Z14: =IFERROR(IF(Transactions!B16="Expense",Transactions!E16+ROW()/10000000,""),"") -> 13.700001 | AA14: =IFERROR(IF(Transactions!B16="Expense",Transactions!A16,""),"") -> 46131 | AB14: =IFERROR(IF(Transactions!B16="Expense",Transactions!C16,""),"") -> Food | AC14: =IFERROR(IF(Transactions!B16="Expense",Transactions!D16,""),"") -> Popeye | AD14: =IFERROR(IF(Transactions!B16="Expense",Transactions!E16,""),"") -> 13.7
B15: Category | C15: Total Spent | D15: % of Expense | E15: # of Txns | F15: Avg per Txn | Z15: =IFERROR(IF(Transactions!B17="Expense",Transactions!E17+ROW()/10000000,""),"") | AA15: =IFERROR(IF(Transactions!B17="Expense",Transactions!A17,""),"") | AB15: =IFERROR(IF(Transactions!B17="Expense",Transactions!C17,""),"") | AC15: =IFERROR(IF(Transactions!B17="Expense",Transactions!D17,""),"") | AD15: =IFERROR(IF(Transactions!B17="Expense",Transactions!E17,""),"")
B16: Food | C16: =SUMIFS(Transactions!E:E,Transactions!B:B,"Expense",Transactions!C:C,"Food") -> 847.14 | D16: =IFERROR(C16/SUMIFS(Transactions!E:E,Transactions!B:B,"Expense"),0) -> 0.19397255 | E16: =COUNTIFS(Transactions!B:B,"Expense",Transactions!C:C,"Food") -> 57 | F16: =IFERROR(C16/E16,0) -> 14.862105 | Z16: =IFERROR(IF(Transactions!B18="Expense",Transactions!E18+ROW()/10000000,""),"") | AA16: =IFERROR(IF(Transactions!B18="Expense",Transactions!A18,""),"") | AB16: =IFERROR(IF(Transactions!B18="Expense",Transactions!C18,""),"") | AC16: =IFERROR(IF(Transactions!B18="Expense",Transactions!D18,""),"") | AD16: =IFERROR(IF(Transactions!B18="Expense",Transactions!E18,""),"")
B17: Transport | C17: =SUMIFS(Transactions!E:E,Transactions!B:B,"Expense",Transactions!C:C,"Transport") -> 110.18 | D17: =IFERROR(C17/SUMIFS(Transactions!E:E,Transactions!B:B,"Expense"),0) -> 0.025228292 | E17: =COUNTIFS(Transactions!B:B,"Expense",Transactions!C:C,"Transport") -> 10 | F17: =IFERROR(C17/E17,0) -> 11.018 | Z17: =IFERROR(IF(Transactions!B19="Expense",Transactions!E19+ROW()/10000000,""),"") -> 13.000002 | AA17: =IFERROR(IF(Transactions!B19="Expense",Transactions!A19,""),"") -> 46131 | AB17: =IFERROR(IF(Transactions!B19="Expense",Transactions!C19,""),"") -> Food | AC17: =IFERROR(IF(Transactions!B19="Expense",Transactions!D19,""),"") -> Subway | AD17: =IFERROR(IF(Transactions!B19="Expense",Transactions!E19,""),"") -> 13
B18: Bills | C18: =SUMIFS(Transactions!E:E,Transactions!B:B,"Expense",Transactions!C:C,"Bills") -> 240 | D18: =IFERROR(C18/SUMIFS(Transactions!E:E,Transactions!B:B,"Expense"),0) -> 0.054953623 | E18: =COUNTIFS(Transactions!B:B,"Expense",Transactions!C:C,"Bills") -> 1 | F18: =IFERROR(C18/E18,0) -> 240 | Z18: =IFERROR(IF(Transactions!B20="Expense",Transactions!E20+ROW()/10000000,""),"") -> 7.1000018 | AA18: =IFERROR(IF(Transactions!B20="Expense",Transactions!A20,""),"") -> 46132 | AB18: =IFERROR(IF(Transactions!B20="Expense",Transactions!C20,""),"") -> Food | AC18: =IFERROR(IF(Transactions!B20="Expense",Transactions!D20,""),"") -> Chicken Rice | AD18: =IFERROR(IF(Transactions!B20="Expense",Transactions!E20,""),"") -> 7.1
B19: Shopping | C19: =SUMIFS(Transactions!E:E,Transactions!B:B,"Expense",Transactions!C:C,"Shopping") -> 486.98 | D19: =IFERROR(C19/SUMIFS(Transactions!E:E,Transactions!B:B,"Expense"),0) -> 0.11150548 | E19: =COUNTIFS(Transactions!B:B,"Expense",Transactions!C:C,"Shopping") -> 20 | F19: =IFERROR(C19/E19,0) -> 24.349 | Z19: =IFERROR(IF(Transactions!B21="Expense",Transactions!E21+ROW()/10000000,""),"") -> 0.2000019 | AA19: =IFERROR(IF(Transactions!B21="Expense",Transactions!A21,""),"") -> 46132 | AB19: =IFERROR(IF(Transactions!B21="Expense",Transactions!C21,""),"") -> Transport | AC19: =IFERROR(IF(Transactions!B21="Expense",Transactions!D21,""),"") -> Bus | AD19: =IFERROR(IF(Transactions!B21="Expense",Transactions!E21,""),"") -> 0.2
B20: Subscription | C20: =SUMIFS(Transactions!E:E,Transactions!B:B,"Expense",Transactions!C:C,"Subscription") -> 437.369 | D20: =IFERROR(C20/SUMIFS(Transactions!E:E,Transactions!B:B,"Expense"),0) -> 0.10014588 | E20: =COUNTIFS(Transactions!B:B,"Expense",Transactions!C:C,"Subscription") -> 18 | F20: =IFERROR(C20/E20,0) -> 24.298278 | Z20: =IFERROR(IF(Transactions!B22="Expense",Transactions!E22+ROW()/10000000,""),"") -> 14.440002 | AA20: =IFERROR(IF(Transactions!B22="Expense",Transactions!A22,""),"") -> 46132 | AB20: =IFERROR(IF(Transactions!B22="Expense",Transactions!C22,""),"") -> Grocery | AC20: =IFERROR(IF(Transactions!B22="Expense",Transactions!D22,""),"") -> Fairprice | AD20: =IFERROR(IF(Transactions!B22="Expense",Transactions!E22,""),"") -> 14.44
B21: Entertainment | C21: =SUMIFS(Transactions!E:E,Transactions!B:B,"Expense",Transactions!C:C,"Entertainment") -> 180 | D21: =IFERROR(C21/SUMIFS(Transactions!E:E,Transactions!B:B,"Expense"),0) -> 0.041215217 | E21: =COUNTIFS(Transactions!B:B,"Expense",Transactions!C:C,"Entertainment") -> 4 | F21: =IFERROR(C21/E21,0) -> 45 | Z21: =IFERROR(IF(Transactions!B23="Expense",Transactions!E23+ROW()/10000000,""),"") -> 18.270002 | AA21: =IFERROR(IF(Transactions!B23="Expense",Transactions!A23,""),"") -> 46132 | AB21: =IFERROR(IF(Transactions!B23="Expense",Transactions!C23,""),"") -> Grocery | AC21: =IFERROR(IF(Transactions!B23="Expense",Transactions!D23,""),"") -> Fairprice | AD21: =IFERROR(IF(Transactions!B23="Expense",Transactions!E23,""),"") -> 18.27
B22: Health | C22: =SUMIFS(Transactions!E:E,Transactions!B:B,"Expense",Transactions!C:C,"Health") -> 0 | D22: =IFERROR(C22/SUMIFS(Transactions!E:E,Transactions!B:B,"Expense"),0) -> 0 | E22: =COUNTIFS(Transactions!B:B,"Expense",Transactions!C:C,"Health") -> 0 | F22: =IFERROR(C22/E22,0) -> 0 | Z22: =IFERROR(IF(Transactions!B24="Expense",Transactions!E24+ROW()/10000000,""),"") -> 5.4000022 | AA22: =IFERROR(IF(Transactions!B24="Expense",Transactions!A24,""),"") -> 46134 | AB22: =IFERROR(IF(Transactions!B24="Expense",Transactions!C24,""),"") -> Food | AC22: =IFERROR(IF(Transactions!B24="Expense",Transactions!D24,""),"") -> Chicken Rice | AD22: =IFERROR(IF(Transactions!B24="Expense",Transactions!E24,""),"") -> 5.4
B23: Family | C23: =SUMIFS(Transactions!E:E,Transactions!B:B,"Expense",Transactions!C:C,"Family") -> 1000 | D23: =IFERROR(C23/SUMIFS(Transactions!E:E,Transactions!B:B,"Expense"),0) -> 0.22897343 | E23: =COUNTIFS(Transactions!B:B,"Expense",Transactions!C:C,"Family") -> 1 | F23: =IFERROR(C23/E23,0) -> 1000 | Z23: =IFERROR(IF(Transactions!B25="Expense",Transactions!E25+ROW()/10000000,""),"") -> 5.1000023 | AA23: =IFERROR(IF(Transactions!B25="Expense",Transactions!A25,""),"") -> 46134 | AB23: =IFERROR(IF(Transactions!B25="Expense",Transactions!C25,""),"") -> Food | AC23: =IFERROR(IF(Transactions!B25="Expense",Transactions!D25,""),"") -> Siew Mai | AD23: =IFERROR(IF(Transactions!B25="Expense",Transactions!E25,""),"") -> 5.1
B24: Travel | C24: =SUMIFS(Transactions!E:E,Transactions!B:B,"Expense",Transactions!C:C,"Travel") -> 563.95 | D24: =IFERROR(C24/SUMIFS(Transactions!E:E,Transactions!B:B,"Expense"),0) -> 0.12912956 | E24: =COUNTIFS(Transactions!B:B,"Expense",Transactions!C:C,"Travel") -> 5 | F24: =IFERROR(C24/E24,0) -> 112.79 | Z24: =IFERROR(IF(Transactions!B26="Expense",Transactions!E26+ROW()/10000000,""),"") -> 3.1000024 | AA24: =IFERROR(IF(Transactions!B26="Expense",Transactions!A26,""),"") -> 46134 | AB24: =IFERROR(IF(Transactions!B26="Expense",Transactions!C26,""),"") -> Grocery | AC24: =IFERROR(IF(Transactions!B26="Expense",Transactions!D26,""),"") -> Fairprice | AD24: =IFERROR(IF(Transactions!B26="Expense",Transactions!E26,""),"") -> 3.1
B25: Education | C25: =SUMIFS(Transactions!E:E,Transactions!B:B,"Expense",Transactions!C:C,"Education") -> 8.88 | D25: =IFERROR(C25/SUMIFS(Transactions!E:E,Transactions!B:B,"Expense"),0) -> 0.002033284 | E25: =COUNTIFS(Transactions!B:B,"Expense",Transactions!C:C,"Education") -> 1 | F25: =IFERROR(C25/E25,0) -> 8.88 | Z25: =IFERROR(IF(Transactions!B27="Expense",Transactions!E27+ROW()/10000000,""),"") -> 0.2000025 | AA25: =IFERROR(IF(Transactions!B27="Expense",Transactions!A27,""),"") -> 46135 | AB25: =IFERROR(IF(Transactions!B27="Expense",Transactions!C27,""),"") -> Transport | AC25: =IFERROR(IF(Transactions!B27="Expense",Transactions!D27,""),"") -> Bus | AD25: =IFERROR(IF(Transactions!B27="Expense",Transactions!E27,""),"") -> 0.2
B26: Misc | C26: =SUMIFS(Transactions!E:E,Transactions!B:B,"Expense",Transactions!C:C,"Misc") -> 199 | D26: =IFERROR(C26/SUMIFS(Transactions!E:E,Transactions!B:B,"Expense"),0) -> 0.045565712 | E26: =COUNTIFS(Transactions!B:B,"Expense",Transactions!C:C,"Misc") -> 4 | F26: =IFERROR(C26/E26,0) -> 49.75 | Z26: =IFERROR(IF(Transactions!B28="Expense",Transactions!E28+ROW()/10000000,""),"") -> 15.100003 | AA26: =IFERROR(IF(Transactions!B28="Expense",Transactions!A28,""),"") -> 46136 | AB26: =IFERROR(IF(Transactions!B28="Expense",Transactions!C28,""),"") -> Food | AC26: =IFERROR(IF(Transactions!B28="Expense",Transactions!D28,""),"") -> Stuffd | AD26: =IFERROR(IF(Transactions!B28="Expense",Transactions!E28,""),"") -> 15.1
B27: Grocery | C27: =SUMIFS(Transactions!E:E,Transactions!B:B,"Expense",Transactions!C:C,"Grocery") -> 238.82 | D27: =IFERROR(C27/SUMIFS(Transactions!E:E,Transactions!B:B,"Expense"),0) -> 0.054683434 | E27: =COUNTIFS(Transactions!B:B,"Expense",Transactions!C:C,"Grocery") -> 14 | F27: =IFERROR(C27/E27,0) -> 17.058571 | Z27: =IFERROR(IF(Transactions!B29="Expense",Transactions!E29+ROW()/10000000,""),"") -> 125 | AA27: =IFERROR(IF(Transactions!B29="Expense",Transactions!A29,""),"") -> 46137 | AB27: =IFERROR(IF(Transactions!B29="Expense",Transactions!C29,""),"") -> Misc | AC27: =IFERROR(IF(Transactions!B29="Expense",Transactions!D29,""),"") -> Donation | AD27: =IFERROR(IF(Transactions!B29="Expense",Transactions!E29,""),"") -> 125
B28: 3. Top 10 Largest Expenses | Z28: =IFERROR(IF(Transactions!B30="Expense",Transactions!E30+ROW()/10000000,""),"") -> 17.980003 | AA28: =IFERROR(IF(Transactions!B30="Expense",Transactions!A30,""),"") -> 46138 | AB28: =IFERROR(IF(Transactions!B30="Expense",Transactions!C30,""),"") -> Subscription | AC28: =IFERROR(IF(Transactions!B30="Expense",Transactions!D30,""),"") -> Youtube | AD28: =IFERROR(IF(Transactions!B30="Expense",Transactions!E30,""),"") -> 17.98
B29: Rank | C29: Date | D29: Category | E29: Description | F29: Amount | Z29: =IFERROR(IF(Transactions!B31="Expense",Transactions!E31+ROW()/10000000,""),"") -> 82.620003 | AA29: =IFERROR(IF(Transactions!B31="Expense",Transactions!A31,""),"") -> 46138 | AB29: =IFERROR(IF(Transactions!B31="Expense",Transactions!C31,""),"") -> Subscription | AC29: =IFERROR(IF(Transactions!B31="Expense",Transactions!D31,""),"") -> AVG Antivirus | AD29: =IFERROR(IF(Transactions!B31="Expense",Transactions!E31,""),"") -> 82.62
B30: 1 | C30: {=IFERROR(INDEX($AA$2:$AA$499,MATCH(LARGE($Z$2:$Z$499,1),$Z$2:$Z$499,0)),"")} -> 46170 | D30: {=IFERROR(INDEX($AB$2:$AB$499,MATCH(LARGE($Z$2:$Z$499,1),$Z$2:$Z$499,0)),"")} -> Family | E30: {=IFERROR(INDEX($AC$2:$AC$499,MATCH(LARGE($Z$2:$Z$499,1),$Z$2:$Z$499,0)),"")} -> Transfer to Parents | F30: {=IFERROR(INDEX($AD$2:$AD$499,MATCH(LARGE($Z$2:$Z$499,1),$Z$2:$Z$499,0)),0)} -> 1000 | Z30: =IFERROR(IF(Transactions!B32="Expense",Transactions!E32+ROW()/10000000,""),"") -> 18.250003 | AA30: =IFERROR(IF(Transactions!B32="Expense",Transactions!A32,""),"") -> 46138 | AB30: =IFERROR(IF(Transactions!B32="Expense",Transactions!C32,""),"") -> Food | AC30: =IFERROR(IF(Transactions!B32="Expense",Transactions!D32,""),"") -> Mcd | AD30: =IFERROR(IF(Transactions!B32="Expense",Transactions!E32,""),"") -> 18.25
B31: 2 | C31: {=IFERROR(INDEX($AA$2:$AA$499,MATCH(LARGE($Z$2:$Z$499,2),$Z$2:$Z$499,0)),"")} -> 46155 | D31: {=IFERROR(INDEX($AB$2:$AB$499,MATCH(LARGE($Z$2:$Z$499,2),$Z$2:$Z$499,0)),"")} -> Travel | E31: {=IFERROR(INDEX($AC$2:$AC$499,MATCH(LARGE($Z$2:$Z$499,2),$Z$2:$Z$499,0)),"")} -> SGD to MYR | F31: {=IFERROR(INDEX($AD$2:$AD$499,MATCH(LARGE($Z$2:$Z$499,2),$Z$2:$Z$499,0)),0)} -> 300 | Z31: =IFERROR(IF(Transactions!B33="Expense",Transactions!E33+ROW()/10000000,""),"") | AA31: =IFERROR(IF(Transactions!B33="Expense",Transactions!A33,""),"") | AB31: =IFERROR(IF(Transactions!B33="Expense",Transactions!C33,""),"") | AC31: =IFERROR(IF(Transactions!B33="Expense",Transactions!D33,""),"") | AD31: =IFERROR(IF(Transactions!B33="Expense",Transactions!E33,""),"")
B32: 3 | C32: {=IFERROR(INDEX($AA$2:$AA$499,MATCH(LARGE($Z$2:$Z$499,3),$Z$2:$Z$499,0)),"")} -> 46148 | D32: {=IFERROR(INDEX($AB$2:$AB$499,MATCH(LARGE($Z$2:$Z$499,3),$Z$2:$Z$499,0)),"")} -> Bills | E32: {=IFERROR(INDEX($AC$2:$AC$499,MATCH(LARGE($Z$2:$Z$499,3),$Z$2:$Z$499,0)),"")} -> Tax | F32: {=IFERROR(INDEX($AD$2:$AD$499,MATCH(LARGE($Z$2:$Z$499,3),$Z$2:$Z$499,0)),0)} -> 240 | Z32: =IFERROR(IF(Transactions!B34="Expense",Transactions!E34+ROW()/10000000,""),"") -> 15.510003 | AA32: =IFERROR(IF(Transactions!B34="Expense",Transactions!A34,""),"") -> 46134 | AB32: =IFERROR(IF(Transactions!B34="Expense",Transactions!C34,""),"") -> Shopping | AC32: =IFERROR(IF(Transactions!B34="Expense",Transactions!D34,""),"") -> Shoppee | AD32: =IFERROR(IF(Transactions!B34="Expense",Transactions!E34,""),"") -> 15.51
B33: 4 | C33: {=IFERROR(INDEX($AA$2:$AA$499,MATCH(LARGE($Z$2:$Z$499,4),$Z$2:$Z$499,0)),"")} -> 46158 | D33: {=IFERROR(INDEX($AB$2:$AB$499,MATCH(LARGE($Z$2:$Z$499,4),$Z$2:$Z$499,0)),"")} -> Travel | E33: {=IFERROR(INDEX($AC$2:$AC$499,MATCH(LARGE($Z$2:$Z$499,4),$Z$2:$Z$499,0)),"")} -> KL Grand Hyatt Deposit | F33: {=IFERROR(INDEX($AD$2:$AD$499,MATCH(LARGE($Z$2:$Z$499,4),$Z$2:$Z$499,0)),0)} -> 199.45 | Z33: =IFERROR(IF(Transactions!B35="Expense",Transactions!E35+ROW()/10000000,""),"") -> 21.160003 | AA33: =IFERROR(IF(Transactions!B35="Expense",Transactions!A35,""),"") -> 46135 | AB33: =IFERROR(IF(Transactions!B35="Expense",Transactions!C35,""),"") -> Shopping | AC33: =IFERROR(IF(Transactions!B35="Expense",Transactions!D35,""),"") -> Shoppee | AD33: =IFERROR(IF(Transactions!B35="Expense",Transactions!E35,""),"") -> 21.16
B34: 5 | C34: {=IFERROR(INDEX($AA$2:$AA$499,MATCH(LARGE($Z$2:$Z$499,5),$Z$2:$Z$499,0)),"")} -> 46137 | D34: {=IFERROR(INDEX($AB$2:$AB$499,MATCH(LARGE($Z$2:$Z$499,5),$Z$2:$Z$499,0)),"")} -> Misc | E34: {=IFERROR(INDEX($AC$2:$AC$499,MATCH(LARGE($Z$2:$Z$499,5),$Z$2:$Z$499,0)),"")} -> Donation | F34: {=IFERROR(INDEX($AD$2:$AD$499,MATCH(LARGE($Z$2:$Z$499,5),$Z$2:$Z$499,0)),0)} -> 125 | Z34: =IFERROR(IF(Transactions!B36="Expense",Transactions!E36+ROW()/10000000,""),"") -> 7.0000034 | AA34: =IFERROR(IF(Transactions!B36="Expense",Transactions!A36,""),"") -> 46138 | AB34: =IFERROR(IF(Transactions!B36="Expense",Transactions!C36,""),"") -> Subscription | AC34: =IFERROR(IF(Transactions!B36="Expense",Transactions!D36,""),"") -> Gomo | AD34: =IFERROR(IF(Transactions!B36="Expense",Transactions!E36,""),"") -> 7
B35: 6 | C35: {=IFERROR(INDEX($AA$2:$AA$499,MATCH(LARGE($Z$2:$Z$499,6),$Z$2:$Z$499,0)),"")} -> 46159 | D35: {=IFERROR(INDEX($AB$2:$AB$499,MATCH(LARGE($Z$2:$Z$499,6),$Z$2:$Z$499,0)),"")} -> Shopping | E35: {=IFERROR(INDEX($AC$2:$AC$499,MATCH(LARGE($Z$2:$Z$499,6),$Z$2:$Z$499,0)),"")} -> KL Shopping | F35: {=IFERROR(INDEX($AD$2:$AD$499,MATCH(LARGE($Z$2:$Z$499,6),$Z$2:$Z$499,0)),0)} -> 116.41 | Z35: =IFERROR(IF(Transactions!B37="Expense",Transactions!E37+ROW()/10000000,""),"") -> 18.000003 | AA35: =IFERROR(IF(Transactions!B37="Expense",Transactions!A37,""),"") -> 46135 | AB35: =IFERROR(IF(Transactions!B37="Expense",Transactions!C37,""),"") -> Food | AC35: =IFERROR(IF(Transactions!B37="Expense",Transactions!D37,""),"") -> Lunch with Team | AD35: =IFERROR(IF(Transactions!B37="Expense",Transactions!E37,""),"") -> 18
B36: 7 | C36: {=IFERROR(INDEX($AA$2:$AA$499,MATCH(LARGE($Z$2:$Z$499,7),$Z$2:$Z$499,0)),"")} -> 46151 | D36: {=IFERROR(INDEX($AB$2:$AB$499,MATCH(LARGE($Z$2:$Z$499,7),$Z$2:$Z$499,0)),"")} -> Food | E36: {=IFERROR(INDEX($AC$2:$AC$499,MATCH(LARGE($Z$2:$Z$499,7),$Z$2:$Z$499,0)),"")} -> Bali Thai Mother's day | F36: {=IFERROR(INDEX($AD$2:$AD$499,MATCH(LARGE($Z$2:$Z$499,7),$Z$2:$Z$499,0)),0)} -> 109.47 | Z36: =IFERROR(IF(Transactions!B38="Expense",Transactions!E38+ROW()/10000000,""),"") | AA36: =IFERROR(IF(Transactions!B38="Expense",Transactions!A38,""),"") | AB36: =IFERROR(IF(Transactions!B38="Expense",Transactions!C38,""),"") | AC36: =IFERROR(IF(Transactions!B38="Expense",Transactions!D38,""),"") | AD36: =IFERROR(IF(Transactions!B38="Expense",Transactions!E38,""),"")
B37: 8 | C37: {=IFERROR(INDEX($AA$2:$AA$499,MATCH(LARGE($Z$2:$Z$499,8),$Z$2:$Z$499,0)),"")} -> 46143 | D37: {=IFERROR(INDEX($AB$2:$AB$499,MATCH(LARGE($Z$2:$Z$499,8),$Z$2:$Z$499,0)),"")} -> Subscription | E37: {=IFERROR(INDEX($AC$2:$AC$499,MATCH(LARGE($Z$2:$Z$499,8),$Z$2:$Z$499,0)),"")} -> Anytime Fitness | F37: {=IFERROR(INDEX($AD$2:$AD$499,MATCH(LARGE($Z$2:$Z$499,8),$Z$2:$Z$499,0)),0)} -> 89 | Z37: =IFERROR(IF(Transactions!B39="Expense",Transactions!E39+ROW()/10000000,""),"") | AA37: =IFERROR(IF(Transactions!B39="Expense",Transactions!A39,""),"") | AB37: =IFERROR(IF(Transactions!B39="Expense",Transactions!C39,""),"") | AC37: =IFERROR(IF(Transactions!B39="Expense",Transactions!D39,""),"") | AD37: =IFERROR(IF(Transactions!B39="Expense",Transactions!E39,""),"")
B38: 9 | C38: {=IFERROR(INDEX($AA$2:$AA$499,MATCH(LARGE($Z$2:$Z$499,9),$Z$2:$Z$499,0)),"")} -> 46138 | D38: {=IFERROR(INDEX($AB$2:$AB$499,MATCH(LARGE($Z$2:$Z$499,9),$Z$2:$Z$499,0)),"")} -> Subscription | E38: {=IFERROR(INDEX($AC$2:$AC$499,MATCH(LARGE($Z$2:$Z$499,9),$Z$2:$Z$499,0)),"")} -> AVG Antivirus | F38: {=IFERROR(INDEX($AD$2:$AD$499,MATCH(LARGE($Z$2:$Z$499,9),$Z$2:$Z$499,0)),0)} -> 82.62 | Z38: =IFERROR(IF(Transactions!B40="Expense",Transactions!E40+ROW()/10000000,""),"") -> 1.2000038 | AA38: =IFERROR(IF(Transactions!B40="Expense",Transactions!A40,""),"") -> 46143 | AB38: =IFERROR(IF(Transactions!B40="Expense",Transactions!C40,""),"") -> Transport | AC38: =IFERROR(IF(Transactions!B40="Expense",Transactions!D40,""),"") -> Parking | AD38: =IFERROR(IF(Transactions!B40="Expense",Transactions!E40,""),"") -> 1.2
B39: 10 | C39: {=IFERROR(INDEX($AA$2:$AA$499,MATCH(LARGE($Z$2:$Z$499,10),$Z$2:$Z$499,0)),"")} -> 46145 | D39: {=IFERROR(INDEX($AB$2:$AB$499,MATCH(LARGE($Z$2:$Z$499,10),$Z$2:$Z$499,0)),"")} -> Entertainment | E39: {=IFERROR(INDEX($AC$2:$AC$499,MATCH(LARGE($Z$2:$Z$499,10),$Z$2:$Z$499,0)),"")} -> Movie | F39: {=IFERROR(INDEX($AD$2:$AD$499,MATCH(LARGE($Z$2:$Z$499,10),$Z$2:$Z$499,0)),0)} -> 80 | Z39: =IFERROR(IF(Transactions!B41="Expense",Transactions!E41+ROW()/10000000,""),"") -> 5.8600039 | AA39: =IFERROR(IF(Transactions!B41="Expense",Transactions!A41,""),"") -> 46138 | AB39: =IFERROR(IF(Transactions!B41="Expense",Transactions!C41,""),"") -> Grocery | AC39: =IFERROR(IF(Transactions!B41="Expense",Transactions!D41,""),"") -> Fairprice | AD39: =IFERROR(IF(Transactions!B41="Expense",Transactions!E41,""),"") -> 5.86
Z40: =IFERROR(IF(Transactions!B42="Expense",Transactions!E42+ROW()/10000000,""),"") -> 7.900004 | AA40: =IFERROR(IF(Transactions!B42="Expense",Transactions!A42,""),"") -> 46139 | AB40: =IFERROR(IF(Transactions!B42="Expense",Transactions!C42,""),"") -> Food | AC40: =IFERROR(IF(Transactions!B42="Expense",Transactions!D42,""),"") -> Wokhey | AD40: =IFERROR(IF(Transactions!B42="Expense",Transactions!E42,""),"") -> 7.9
B41: 4. Subscription Spending Total | Z41: =IFERROR(IF(Transactions!B43="Expense",Transactions!E43+ROW()/10000000,""),"") -> 0.1700041 | AA41: =IFERROR(IF(Transactions!B43="Expense",Transactions!A43,""),"") -> 46139 | AB41: =IFERROR(IF(Transactions!B43="Expense",Transactions!C43,""),"") -> Food | AC41: =IFERROR(IF(Transactions!B43="Expense",Transactions!D43,""),"") | AD41: =IFERROR(IF(Transactions!B43="Expense",Transactions!E43,""),"") -> 0.17
...
